Workbook

Sheet Read Me First
A1: v2026.04.17
A2: This builds upon Gear Skeptic's extensive videos and associated work on Hiker Food 2.5, for which I'm deeply grateful.
A5: How this Google Sheet works:
A6: Make a copy so you can edit it: File > Make a Copy
A8: Use the Multi-Day Planner to map out each day's meals:
B9: Start typing and any relevant items already in Hiker Food will appear
B10: Look at Color Keys to understand different weight, fat, carbs/protein, and salt ratios
B11: Skip any meal you like
B12: If you need to add a 4th (5th, 6th...) item to a meal, insert a row and add it in the middle of that section, not at the bottom
A13: Repeat for each day of your trip before restock
B14: Use the Shopping List to help with what to buy
A15: Something missing? Add a new row to Hiker Food but not at the very bottom
B16: If you add it to a blank row at the bottom, it won't be included in the dropdowns or calculators
B17: Instead, insert a row anywhere else
B18: Fill out all the relevant details if you care about the calculations
B19: Once you're done, it'll be available in the planner
A21: Notes:
B22: Original Reddit thread regarding a beta of this sheet
B23: I made some edits to Hiker Food 2.5:
C24: To make the pre-selected drop-downs work, I merged Hiker Food and Dried Meals into a single sheet
C25: I modified some colors, largely making "ideal" stuff shades of green instead of the original shades of oranges and reds
C26: Some of the formulas showed errors because they divided by zero. While I'm a backpacker by heart, I'm a spreadsheet nerd by day and this bothered me. So now these show N/A rather than an error.
B27: Electrolytes and NaK Calculator are untouched from the original Hiker Food 2.5
A29: Changelog
B30: Added grams to the Multi-Day Planner, it's currently only in ounces.
B31: Fixed a bug where the dropdown options for the planner weren't fixed to the top of the hiker food list
B32: Adjusted the tab layout

Sheet Multi-day planner
A1: Day | B1: Meal | C1: Item | D1: Qty | E1: Oz | F1: Gr | G1: Fat | H1: NA | I1: K | J1: Carbs | K1: Fiber | L1: Sugar | M1: Other | N1: Protein | O1: Cal | P1: Carb/Pro | Q1: Fat % | R1: Sugar % | S1: Na/kcal | T1: Sum | U1: Oz/kcal | V1: Oz | W1: Gr/kcal | X1: Gr | Y1: Kcal | Z1: Carb/Pro | AA1: Fat % | AB1: Sugar % | AC1: Na/kcal
A2: 1 | B2: Breakfast | C2: Backpacker's Pantry Granola with Bananas & Milk | D2: 1 | E2: {=if(C2="","",_xlfn.xlookup(C2,'Hiker Food'!$C:$C,'Hiker Food'!G:G)*D2)} -> 4.7619887 | F2: {=if(C2="","",_xlfn.xlookup(C2,'Hiker Food'!$C:$C,'Hiker Food'!H:H)*D2)} -> 135 | G2: {=if($C2="","",_xlfn.xlookup($C2,'Hiker Food'!$C:$C,'Hiker Food'!J:J)*$D2)} -> 31 | H2: {=if($C2="","",_xlfn.xlookup($C2,'Hiker Food'!$C:$C,'Hiker Food'!K:K)*$D2)} -> 280 | I2: {=if($C2="","",_xlfn.xlookup($C2,'Hiker Food'!$C:$C,'Hiker Food'!L:L)*$D2)} -> 0 | J2: {=if($C2="","",_xlfn.xlookup($C2,'Hiker Food'!$C:$C,'Hiker Food'!M:M)*$D2)} -> 74 | K2: {=if($C2="","",_xlfn.xlookup($C2,'Hiker Food'!$C:$C,'Hiker Food'!N:N)*$D2)} -> 7 | L2: {=if($C2="","",_xlfn.xlookup($C2,'Hiker Food'!$C:$C,'Hiker Food'!O:O)*$D2)} -> 32 | M2: {=if($C2="","",_xlfn.xlookup($C2,'Hiker Food'!$C:$C,'Hiker Food'!P:P)*$D2)} -> 35 | N2: {=if($C2="","",_xlfn.xlookup($C2,'Hiker Food'!$C:$C,'Hiker Food'!Q:Q)*$D2)} -> 17 | O2: {=if($C2="","",_xlfn.xlookup($C2,'Hiker Food'!$C:$C,'Hiker Food'!I:I)*$D2)} -> 620 | P2: {=if($C2="","",_xlfn.xlookup($C2,'Hiker Food'!$C:$C,'Hiker Food'!T:T))} -> 4.3529412 | Q2: {=if($C2="","",_xlfn.xlookup($C2,'Hiker Food'!$C:$C,'Hiker Food'!U:U))} -> 0.43390358 | R2: {=if($C2="","",_xlfn.xlookup($C2,'Hiker Food'!$C:$C,'Hiker Food'!V:V))} -> 0.19906687 | S2: {=if($C2="","",_xlfn.xlookup($C2,'Hiker Food'!$C:$C,'Hiker Food'!W:W))} -> 0.4516129 | T2: Breakfast | U2: =if($C2="","",$Y2/V2) -> 130.1977 | V2: =if($C2="","",sum(E2:E4)) -> 4.7619887 | W2: =if($C2="","",$Y2/X2) -> 4.5925926 | X2: =if($C2="","",sum(F2:F4)) -> 135 | Y2: =if($C2="","",sum(O2:O4)) -> 620 | Z2: =if($C2="","",(sum(J2:J4)/sum(N2:N4))) -> 4.3529412 | AA2: =if($C2="","",sum(G2:G4)*9/sum(sum(G2:G4)*9+sum(J2:J4)*4+sum(N2:N4)*4)) -> 0.43390358 | AB2: =if($C2="","",sum(L2:L4)*4/sum(sum(G2:G4)*9+sum(J2:J4)*4+sum(N2:N4)*4)) -> 0.19906687 | AC2: =if($C2="","",(sum(H2:H4)/sum(O2:O4))) -> 0.4516129
D3: 1 | E3: {=if(C3="","",_xlfn.xlookup(C3,'Hiker Food'!$C:$C,'Hiker Food'!G:G)*D3)} | F3: {=if(C3="","",_xlfn.xlookup(C3,'Hiker Food'!$C:$C,'Hiker Food'!H:H)*D3)} | G3: {=if($C3="","",_xlfn.xlookup($C3,'Hiker Food'!$C:$C,'Hiker Food'!J:J)*$D3)} | H3: {=if($C3="","",_xlfn.xlookup($C3,'Hiker Food'!$C:$C,'Hiker Food'!K:K)*$D3)} | I3: {=if($C3="","",_xlfn.xlookup($C3,'Hiker Food'!$C:$C,'Hiker Food'!L:L)*$D3)} | J3: {=if($C3="","",_xlfn.xlookup($C3,'Hiker Food'!$C:$C,'Hiker Food'!M:M)*$D3)} | K3: {=if($C3="","",_xlfn.xlookup($C3,'Hiker Food'!$C:$C,'Hiker Food'!N:N)*$D3)} | L3: {=if($C3="","",_xlfn.xlookup($C3,'Hiker Food'!$C:$C,'Hiker Food'!O:O)*$D3)} | M3: {=if($C3="","",_xlfn.xlookup($C3,'Hiker Food'!$C:$C,'Hiker Food'!P:P)*$D3)} | N3: {=if($C3="","",_xlfn.xlookup($C3,'Hiker Food'!$C:$C,'Hiker Food'!Q:Q)*$D3)} | O3: {=if($C3="","",_xlfn.xlookup($C3,'Hiker Food'!$C:$C,'Hiker Food'!I:I)*$D3)} | P3: {=if($C3="","",_xlfn.xlookup($C3,'Hiker Food'!$C:$C,'Hiker Food'!T:T))} | Q3: {=if($C3="","",_xlfn.xlookup($C3,'Hiker Food'!$C:$C,'Hiker Food'!U:U))} | R3: {=if($C3="","",_xlfn.xlookup($C3,'Hiker Food'!$C:$C,'Hiker Food'!V:V))} | S3: {=if($C3="","",_xlfn.xlookup($C3,'Hiker Food'!$C:$C,'Hiker Food'!W:W))}
D4: 1 | E4: {=if(C4="","",_xlfn.xlookup(C4,'Hiker Food'!$C:$C,'Hiker Food'!G:G)*D4)} | F4: {=if(C4="","",_xlfn.xlookup(C4,'Hiker Food'!$C:$C,'Hiker Food'!H:H)*D4)} | G4: {=if($C4="","",_xlfn.xlookup($C4,'Hiker Food'!$C:$C,'Hiker Food'!J:J)*$D4)} | H4: {=if($C4="","",_xlfn.xlookup($C4,'Hiker Food'!$C:$C,'Hiker Food'!K:K)*$D4)} | I4: {=if($C4="","",_xlfn.xlookup($C4,'Hiker Food'!$C:$C,'Hiker Food'!L:L)*$D4)} | J4: {=if($C4="","",_xlfn.xlookup($C4,'Hiker Food'!$C:$C,'Hiker Food'!M:M)*$D4)} | K4: {=if($C4="","",_xlfn.xlookup($C4,'Hiker Food'!$C:$C,'Hiker Food'!N:N)*$D4)} | L4: {=if($C4="","",_xlfn.xlookup($C4,'Hiker Food'!$C:$C,'Hiker Food'!O:O)*$D4)} | M4: {=if($C4="","",_xlfn.xlookup($C4,'Hiker Food'!$C:$C,'Hiker Food'!P:P)*$D4)} | N4: {=if($C4="","",_xlfn.xlookup($C4,'Hiker Food'!$C:$C,'Hiker Food'!Q:Q)*$D4)} | O4: {=if($C4="","",_xlfn.xlookup($C4,'Hiker Food'!$C:$C,'Hiker Food'!I:I)*$D4)} | P4: {=if($C4="","",_xlfn.xlookup($C4,'Hiker Food'!$C:$C,'Hiker Food'!T:T))} | Q4: {=if($C4="","",_xlfn.xlookup($C4,'Hiker Food'!$C:$C,'Hiker Food'!U:U))} | R4: {=if($C4="","",_xlfn.xlookup($C4,'Hiker Food'!$C:$C,'Hiker Food'!V:V))} | S4: {=if($C4="","",_xlfn.xlookup($C4,'Hiker Food'!$C:$C,'Hiker Food'!W:W))}
B5: Morning Snacks | C5: Honey Stinger Waffle, Short Stack with Maple | D5: 2 | E5: {=if(C5="","",_xlfn.xlookup(C5,'Hiker Food'!$C:$C,'Hiker Food'!G:G)*D5)} -> 2.1164394 | F5: {=if(C5="","",_xlfn.xlookup(C5,'Hiker Food'!$C:$C,'Hiker Food'!H:H)*D5)} -> 60 | G5: {=if($C5="","",_xlfn.xlookup($C5,'Hiker Food'!$C:$C,'Hiker Food'!J:J)*$D5)} -> 14 | H5: {=if($C5="","",_xlfn.xlookup($C5,'Hiker Food'!$C:$C,'Hiker Food'!K:K)*$D5)} -> 110 | I5: {=if($C5="","",_xlfn.xlookup($C5,'Hiker Food'!$C:$C,'Hiker Food'!L:L)*$D5)} -> 0 | J5: {=if($C5="","",_xlfn.xlookup($C5,'Hiker Food'!$C:$C,'Hiker Food'!M:M)*$D5)} -> 38 | K5: {=if($C5="","",_xlfn.xlookup($C5,'Hiker Food'!$C:$C,'Hiker Food'!N:N)*$D5)} -> 2 | L5: {=if($C5="","",_xlfn.xlookup($C5,'Hiker Food'!$C:$C,'Hiker Food'!O:O)*$D5)} -> 20 | M5: {=if($C5="","",_xlfn.xlookup($C5,'Hiker Food'!$C:$C,'Hiker Food'!P:P)*$D5)} -> 16 | N5: {=if($C5="","",_xlfn.xlookup($C5,'Hiker Food'!$C:$C,'Hiker Food'!Q:Q)*$D5)} -> 2 | O5: {=if($C5="","",_xlfn.xlookup($C5,'Hiker Food'!$C:$C,'Hiker Food'!I:I)*$D5)} -> 300 | P5: {=if($C5="","",_xlfn.xlookup($C5,'Hiker Food'!$C:$C,'Hiker Food'!T:T))} -> 19 | Q5: {=if($C5="","",_xlfn.xlookup($C5,'Hiker Food'!$C:$C,'Hiker Food'!U:U))} -> 0.44055944 | R5: {=if($C5="","",_xlfn.xlookup($C5,'Hiker Food'!$C:$C,'Hiker Food'!V:V))} -> 0.27972028 | S5: {=if($C5="","",_xlfn.xlookup($C5,'Hiker Food'!$C:$C,'Hiker Food'!W:W))} -> 0.36666667 | T5: Morning Snacks | U5: =if(C5="","",Y5/V5) -> 164.61 | V5: =if($C5="","",sum(E5:E7)) -> 4.3739748 | W5: =if($C5="","",$Y5/X5) -> 5.8064516 | X5: =if($C5="","",sum(F5:F7)) -> 124 | Y5: =if($C5="","",sum(O5:O7)) -> 720 | Z5: =if($C5="","",(sum(J5:J7)/sum(N5:N7))) -> 3.125 | AA5: =if($C5="","",sum(G5:G7)*9/sum(sum(G5:G7)*9+sum(J5:J7)*4+sum(N5:N7)*4)) -> 0.6302521 | AB5: =if($C5="","",sum(L5:L7)*4/sum(sum(G5:G7)*9+sum(J5:J7)*4+sum(N5:N7)*4)) -> 0.13445378 | AC5: =if($C5="","",(sum(H5:H7)/sum(O5:O7))) -> 0.22222222
C6: Justin's Classic Peanut Butter | D6: 2 | E6: {=if(C6="","",_xlfn.xlookup(C6,'Hiker Food'!$C:$C,'Hiker Food'!G:G)*D6)} -> 2.2575354 | F6: {=if(C6="","",_xlfn.xlookup(C6,'Hiker Food'!$C:$C,'Hiker Food'!H:H)*D6)} -> 64 | G6: {=if($C6="","",_xlfn.xlookup($C6,'Hiker Food'!$C:$C,'Hiker Food'!J:J)*$D6)} -> 36 | H6: {=if($C6="","",_xlfn.xlookup($C6,'Hiker Food'!$C:$C,'Hiker Food'!K:K)*$D6)} -> 50 | I6: {=if($C6="","",_xlfn.xlookup($C6,'Hiker Food'!$C:$C,'Hiker Food'!L:L)*$D6)} -> 180 | J6: {=if($C6="","",_xlfn.xlookup($C6,'Hiker Food'!$C:$C,'Hiker Food'!M:M)*$D6)} -> 12 | K6: {=if($C6="","",_xlfn.xlookup($C6,'Hiker Food'!$C:$C,'Hiker Food'!N:N)*$D6)} -> 2 | L6: {=if($C6="","",_xlfn.xlookup($C6,'Hiker Food'!$C:$C,'Hiker Food'!O:O)*$D6)} -> 4 | M6: {=if($C6="","",_xlfn.xlookup($C6,'Hiker Food'!$C:$C,'Hiker Food'!P:P)*$D6)} -> 6 | N6: {=if($C6="","",_xlfn.xlookup($C6,'Hiker Food'!$C:$C,'Hiker Food'!Q:Q)*$D6)} -> 14 | O6: {=if($C6="","",_xlfn.xlookup($C6,'Hiker Food'!$C:$C,'Hiker Food'!I:I)*$D6)} -> 420 | P6: {=if($C6="","",_xlfn.xlookup($C6,'Hiker Food'!$C:$C,'Hiker Food'!T:T))} -> 0.85714286 | Q6: {=if($C6="","",_xlfn.xlookup($C6,'Hiker Food'!$C:$C,'Hiker Food'!U:U))} -> 0.75700935 | R6: {=if($C6="","",_xlfn.xlookup($C6,'Hiker Food'!$C:$C,'Hiker Food'!V:V))} -> 0.037383178 | S6: {=if($C6="","",_xlfn.xlookup($C6,'Hiker Food'!$C:$C,'Hiker Food'!W:W))} -> 0.11904762
D7: 1 | E7: {=if(C7="","",_xlfn.xlookup(C7,'Hiker Food'!$C:$C,'Hiker Food'!G:G)*D7)} | F7: {=if(C7="","",_xlfn.xlookup(C7,'Hiker Food'!$C:$C,'Hiker Food'!H:H)*D7)} | G7: {=if($C7="","",_xlfn.xlookup($C7,'Hiker Food'!$C:$C,'Hiker Food'!J:J)*$D7)} | H7: {=if($C7="","",_xlfn.xlookup($C7,'Hiker Food'!$C:$C,'Hiker Food'!K:K)*$D7)} | I7: {=if($C7="","",_xlfn.xlookup($C7,'Hiker Food'!$C:$C,'Hiker Food'!L:L)*$D7)} | J7: {=if($C7="","",_xlfn.xlookup($C7,'Hiker Food'!$C:$C,'Hiker Food'!M:M)*$D7)} | K7: {=if($C7="","",_xlfn.xlookup($C7,'Hiker Food'!$C:$C,'Hiker Food'!N:N)*$D7)} | L7: {=if($C7="","",_xlfn.xlookup($C7,'Hiker Food'!$C:$C,'Hiker Food'!O:O)*$D7)} | M7: {=if($C7="","",_xlfn.xlookup($C7,'Hiker Food'!$C:$C,'Hiker Food'!P:P)*$D7)} | N7: {=if($C7="","",_xlfn.xlookup($C7,'Hiker Food'!$C:$C,'Hiker Food'!Q:Q)*$D7)} | O7: {=if($C7="","",_xlfn.xlookup($C7,'Hiker Food'!$C:$C,'Hiker Food'!I:I)*$D7)} | P7: {=if($C7="","",_xlfn.xlookup($C7,'Hiker Food'!$C:$C,'Hiker Food'!T:T))} | Q7: {=if($C7="","",_xlfn.xlookup($C7,'Hiker Food'!$C:$C,'Hiker Food'!U:U))} | R7: {=if($C7="","",_xlfn.xlookup($C7,'Hiker Food'!$C:$C,'Hiker Food'!V:V))} | S7: {=if($C7="","",_xlfn.xlookup($C7,'Hiker Food'!$C:$C,'Hiker Food'!W:W))}
B8: Lunch | C8: Open Nature Uncured Hot Italian Salami | D8: 3 | E8: {=if(C8="","",_xlfn.xlookup(C8,'Hiker Food'!$C:$C,'Hiker Food'!G:G)*D8)} -> 2.9630152 | F8: {=if(C8="","",_xlfn.xlookup(C8,'Hiker Food'!$C:$C,'Hiker Food'!H:H)*D8)} -> 84 | G8: {=if($C8="","",_xlfn.xlookup($C8,'Hiker Food'!$C:$C,'Hiker Food'!J:J)*$D8)} -> 30 | H8: {=if($C8="","",_xlfn.xlookup($C8,'Hiker Food'!$C:$C,'Hiker Food'!K:K)*$D8)} -> 1320 | I8: {=if($C8="","",_xlfn.xlookup($C8,'Hiker Food'!$C:$C,'Hiker Food'!L:L)*$D8)} -> 0 | J8: {=if($C8="","",_xlfn.xlookup($C8,'Hiker Food'!$C:$C,'Hiker Food'!M:M)*$D8)} -> 3 | K8: {=if($C8="","",_xlfn.xlookup($C8,'Hiker Food'!$C:$C,'Hiker Food'!N:N)*$D8)} -> 0 | L8: {=if($C8="","",_xlfn.xlookup($C8,'Hiker Food'!$C:$C,'Hiker Food'!O:O)*$D8)} -> 0 | M8: {=if($C8="","",_xlfn.xlookup($C8,'Hiker Food'!$C:$C,'Hiker Food'!P:P)*$D8)} -> 3 | N8: {=if($C8="","",_xlfn.xlookup($C8,'Hiker Food'!$C:$C,'Hiker Food'!Q:Q)*$D8)} -> 18 | O8: {=if($C8="","",_xlfn.xlookup($C8,'Hiker Food'!$C:$C,'Hiker Food'!I:I)*$D8)} -> 330 | P8: {=if($C8="","",_xlfn.xlookup($C8,'Hiker Food'!$C:$C,'Hiker Food'!T:T))} -> 0.16666667 | Q8: {=if($C8="","",_xlfn.xlookup($C8,'Hiker Food'!$C:$C,'Hiker Food'!U:U))} -> 0.76271186 | R8: {=if($C8="","",_xlfn.xlookup($C8,'Hiker Food'!$C:$C,'Hiker Food'!V:V))} -> 0% | S8: {=if($C8="","",_xlfn.xlookup($C8,'Hiker Food'!$C:$C,'Hiker Food'!W:W))} -> 4 | T8: Lunch | U8: =if(C8="","",Y8/V8) -> 115.71224 | V8: =if($C8="","",sum(E8:E10)) -> 5.1852766 | W8: =if($C8="","",$Y8/X8) -> 4.0816327 | X8: =if($C8="","",sum(F8:F10)) -> 147 | Y8: =if($C8="","",sum(O8:O10)) -> 600 | Z8: =if($C8="","",(sum(J8:J10)/sum(N8:N10))) -> 0.18181818 | AA8: =if($C8="","",sum(G8:G10)*9/sum(sum(G8:G10)*9+sum(J8:J10)*4+sum(N8:N10)*4)) -> 0.74634146 | AB8: =if($C8="","",sum(L8:L10)*4/sum(sum(G8:G10)*9+sum(J8:J10)*4+sum(N8:N10)*4)) -> 0 | AC8: =if($C8="","",(sum(H8:H10)/sum(O8:O10))) -> 2.95
C9: Tillamook Cheese packet, Medium Cheddar | D9: 3 | E9: {=if(C9="","",_xlfn.xlookup(C9,'Hiker Food'!$C:$C,'Hiker Food'!G:G)*D9)} -> 2.2222614 | F9: {=if(C9="","",_xlfn.xlookup(C9,'Hiker Food'!$C:$C,'Hiker Food'!H:H)*D9)} -> 63 | G9: {=if($C9="","",_xlfn.xlookup($C9,'Hiker Food'!$C:$C,'Hiker Food'!J:J)*$D9)} -> 21 | H9: {=if($C9="","",_xlfn.xlookup($C9,'Hiker Food'!$C:$C,'Hiker Food'!K:K)*$D9)} -> 450 | I9: {=if($C9="","",_xlfn.xlookup($C9,'Hiker Food'!$C:$C,'Hiker Food'!L:L)*$D9)} -> 0 | J9: {=if($C9="","",_xlfn.xlookup($C9,'Hiker Food'!$C:$C,'Hiker Food'!M:M)*$D9)} -> 3 | K9: {=if($C9="","",_xlfn.xlookup($C9,'Hiker Food'!$C:$C,'Hiker Food'!N:N)*$D9)} -> 0 | L9: {=if($C9="","",_xlfn.xlookup($C9,'Hiker Food'!$C:$C,'Hiker Food'!O:O)*$D9)} -> 0 | M9: {=if($C9="","",_xlfn.xlookup($C9,'Hiker Food'!$C:$C,'Hiker Food'!P:P)*$D9)} -> 3 | N9: {=if($C9="","",_xlfn.xlookup($C9,'Hiker Food'!$C:$C,'Hiker Food'!Q:Q)*$D9)} -> 15 | O9: {=if($C9="","",_xlfn.xlookup($C9,'Hiker Food'!$C:$C,'Hiker Food'!I:I)*$D9)} -> 270 | P9: {=if($C9="","",_xlfn.xlookup($C9,'Hiker Food'!$C:$C,'Hiker Food'!T:T))} -> 0.2 | Q9: {=if($C9="","",_xlfn.xlookup($C9,'Hiker Food'!$C:$C,'Hiker Food'!U:U))} -> 0.72413793 | R9: {=if($C9="","",_xlfn.xlookup($C9,'Hiker Food'!$C:$C,'Hiker Food'!V:V))} -> 0% | S9: {=if($C9="","",_xlfn.xlookup($C9,'Hiker Food'!$C:$C,'Hiker Food'!W:W))} -> 1.6666667
D10: 1 | E10: {=if(C10="","",_xlfn.xlookup(C10,'Hiker Food'!$C:$C,'Hiker Food'!G:G)*D10)} | F10: {=if(C10="","",_xlfn.xlookup(C10,'Hiker Food'!$C:$C,'Hiker Food'!H:H)*D10)} | G10: {=if($C10="","",_xlfn.xlookup($C10,'Hiker Food'!$C:$C,'Hiker Food'!J:J)*$D10)} | H10: {=if($C10="","",_xlfn.xlookup($C10,'Hiker Food'!$C:$C,'Hiker Food'!K:K)*$D10)} | I10: {=if($C10="","",_xlfn.xlookup($C10,'Hiker Food'!$C:$C,'Hiker Food'!L:L)*$D10)} | J10: {=if($C10="","",_xlfn.xlookup($C10,'Hiker Food'!$C:$C,'Hiker Food'!M:M)*$D10)} | K10: {=if($C10="","",_xlfn.xlookup($C10,'Hiker Food'!$C:$C,'Hiker Food'!N:N)*$D10)} | L10: {=if($C10="","",_xlfn.xlookup($C10,'Hiker Food'!$C:$C,'Hiker Food'!O:O)*$D10)} | M10: {=if($C10="","",_xlfn.xlookup($C10,'Hiker Food'!$C:$C,'Hiker Food'!P:P)*$D10)} | N10: {=if($C10="","",_xlfn.xlookup($C10,'Hiker Food'!$C:$C,'Hiker Food'!Q:Q)*$D10)} | O10: {=if($C10="","",_xlfn.xlookup($C10,'Hiker Food'!$C:$C,'Hiker Food'!I:I)*$D10)} | P10: {=if($C10="","",_xlfn.xlookup($C10,'Hiker Food'!$C:$C,'Hiker Food'!T:T))} | Q10: {=if($C10="","",_xlfn.xlookup($C10,'Hiker Food'!$C:$C,'Hiker Food'!U:U))} | R10: {=if($C10="","",_xlfn.xlookup($C10,'Hiker Food'!$C:$C,'Hiker Food'!V:V))} | S10: {=if($C10="","",_xlfn.xlookup($C10,'Hiker Food'!$C:$C,'Hiker Food'!W:W))}
B11: Afternoon Snacks | C11: Safeway (bulk dispenser) Mountain Mix | D11: 1 | E11: {=if(C11="","",_xlfn.xlookup(C11,'Hiker Food'!$C:$C,'Hiker Food'!G:G)*D11)} -> 1.4109596 | F11: {=if(C11="","",_xlfn.xlookup(C11,'Hiker Food'!$C:$C,'Hiker Food'!H:H)*D11)} -> 40 | G11: {=if($C11="","",_xlfn.xlookup($C11,'Hiker Food'!$C:$C,'Hiker Food'!J:J)*$D11)} -> 11 | H11: {=if($C11="","",_xlfn.xlookup($C11,'Hiker Food'!$C:$C,'Hiker Food'!K:K)*$D11)} -> 62 | I11: {=if($C11="","",_xlfn.xlookup($C11,'Hiker Food'!$C:$C,'Hiker Food'!L:L)*$D11)} -> 0 | J11: {=if($C11="","",_xlfn.xlookup($C11,'Hiker Food'!$C:$C,'Hiker Food'!M:M)*$D11)} -> 21 | K11: {=if($C11="","",_xlfn.xlookup($C11,'Hiker Food'!$C:$C,'Hiker Food'!N:N)*$D11)} -> 3 | L11: {=if($C11="","",_xlfn.xlookup($C11,'Hiker Food'!$C:$C,'Hiker Food'!O:O)*$D11)} -> 16 | M11: {=if($C11="","",_xlfn.xlookup($C11,'Hiker Food'!$C:$C,'Hiker Food'!P:P)*$D11)} -> 2 | N11: {=if($C11="","",_xlfn.xlookup($C11,'Hiker Food'!$C:$C,'Hiker Food'!Q:Q)*$D11)} -> 5 | O11: {=if($C11="","",_xlfn.xlookup($C11,'Hiker Food'!$C:$C,'Hiker Food'!I:I)*$D11)} -> 190 | P11: {=if($C11="","",_xlfn.xlookup($C11,'Hiker Food'!$C:$C,'Hiker Food'!T:T))} -> 4.2 | Q11: {=if($C11="","",_xlfn.xlookup($C11,'Hiker Food'!$C:$C,'Hiker Food'!U:U))} -> 0.48768473 | R11: {=if($C11="","",_xlfn.xlookup($C11,'Hiker Food'!$C:$C,'Hiker Food'!V:V))} -> 0.31527094 | S11: {=if($C11="","",_xlfn.xlookup($C11,'Hiker Food'!$C:$C,'Hiker Food'!W:W))} -> 0.32631579 | T11: Afternoon Snacks | U11: =if(C11="","",Y11/V11) -> 134.66012 | V11: =if($C11="","",sum(E11:E13)) -> 2.8219193 | W11: =if($C11="","",$Y11/X11) -> 4.75 | X11: =if($C11="","",sum(F11:F13)) -> 80 | Y11: =if($C11="","",sum(O11:O13)) -> 380 | Z11: =if($C11="","",(sum(J11:J13)/sum(N11:N13))) -> 3.7 | AA11: =if($C11="","",sum(G11:G13)*9/sum(sum(G11:G13)*9+sum(J11:J13)*4+sum(N11:N13)*4)) -> 0.55450237 | AB11: =if($C11="","",sum(L11:L13)*4/sum(sum(G11:G13)*9+sum(J11:J13)*4+sum(N11:N13)*4)) -> 0.19905213 | AC11: =if($C11="","",(sum(H11:H13)/sum(O11:O13))) -> 0.43947368
C12: Kind Salted Caramel Dark Chocolate Nut | D12: 1 | E12: {=if(C12="","",_xlfn.xlookup(C12,'Hiker Food'!$C:$C,'Hiker Food'!G:G)*D12)} -> 1.4109596 | F12: {=if(C12="","",_xlfn.xlookup(C12,'Hiker Food'!$C:$C,'Hiker Food'!H:H)*D12)} -> 40 | G12: {=if($C12="","",_xlfn.xlookup($C12,'Hiker Food'!$C:$C,'Hiker Food'!J:J)*$D12)} -> 15 | H12: {=if($C12="","",_xlfn.xlookup($C12,'Hiker Food'!$C:$C,'Hiker Food'!K:K)*$D12)} -> 105 | I12: {=if($C12="","",_xlfn.xlookup($C12,'Hiker Food'!$C:$C,'Hiker Food'!L:L)*$D12)} -> 200 | J12: {=if($C12="","",_xlfn.xlookup($C12,'Hiker Food'!$C:$C,'Hiker Food'!M:M)*$D12)} -> 16 | K12: {=if($C12="","",_xlfn.xlookup($C12,'Hiker Food'!$C:$C,'Hiker Food'!N:N)*$D12)} -> 7 | L12: {=if($C12="","",_xlfn.xlookup($C12,'Hiker Food'!$C:$C,'Hiker Food'!O:O)*$D12)} -> 5 | M12: {=if($C12="","",_xlfn.xlookup($C12,'Hiker Food'!$C:$C,'Hiker Food'!P:P)*$D12)} -> 4 | N12: {=if($C12="","",_xlfn.xlookup($C12,'Hiker Food'!$C:$C,'Hiker Food'!Q:Q)*$D12)} -> 5 | O12: {=if($C12="","",_xlfn.xlookup($C12,'Hiker Food'!$C:$C,'Hiker Food'!I:I)*$D12)} -> 190 | P12: {=if($C12="","",_xlfn.xlookup($C12,'Hiker Food'!$C:$C,'Hiker Food'!T:T))} -> 3.2 | Q12: {=if($C12="","",_xlfn.xlookup($C12,'Hiker Food'!$C:$C,'Hiker Food'!U:U))} -> 0.61643836 | R12: {=if($C12="","",_xlfn.xlookup($C12,'Hiker Food'!$C:$C,'Hiker Food'!V:V))} -> 0.091324201 | S12: {=if($C12="","",_xlfn.xlookup($C12,'Hiker Food'!$C:$C,'Hiker Food'!W:W))} -> 0.55263158
D13: 1 | E13: {=if(C13="","",_xlfn.xlookup(C13,'Hiker Food'!$C:$C,'Hiker Food'!G:G)*D13)} | F13: {=if(C13="","",_xlfn.xlookup(C13,'Hiker Food'!$C:$C,'Hiker Food'!H:H)*D13)} | G13: {=if($C13="","",_xlfn.xlookup($C13,'Hiker Food'!$C:$C,'Hiker Food'!J:J)*$D13)} | H13: {=if($C13="","",_xlfn.xlookup($C13,'Hiker Food'!$C:$C,'Hiker Food'!K:K)*$D13)} | I13: {=if($C13="","",_xlfn.xlookup($C13,'Hiker Food'!$C:$C,'Hiker Food'!L:L)*$D13)} | J13: {=if($C13="","",_xlfn.xlookup($C13,'Hiker Food'!$C:$C,'Hiker Food'!M:M)*$D13)} | K13: {=if($C13="","",_xlfn.xlookup($C13,'Hiker Food'!$C:$C,'Hiker Food'!N:N)*$D13)} | L13: {=if($C13="","",_xlfn.xlookup($C13,'Hiker Food'!$C:$C,'Hiker Food'!O:O)*$D13)} | M13: {=if($C13="","",_xlfn.xlookup($C13,'Hiker Food'!$C:$C,'Hiker Food'!P:P)*$D13)} | N13: {=if($C13="","",_xlfn.xlookup($C13,'Hiker Food'!$C:$C,'Hiker Food'!Q:Q)*$D13)} | O13: {=if($C13="","",_xlfn.xlookup($C13,'Hiker Food'!$C:$C,'Hiker Food'!I:I)*$D13)} | P13: {=if($C13="","",_xlfn.xlookup($C13,'Hiker Food'!$C:$C,'Hiker Food'!T:T))} | Q13: {=if($C13="","",_xlfn.xlookup($C13,'Hiker Food'!$C:$C,'Hiker Food'!U:U))} | R13: {=if($C13="","",_xlfn.xlookup($C13,'Hiker Food'!$C:$C,'Hiker Food'!V:V))} | S13: {=if($C13="","",_xlfn.xlookup($C13,'Hiker Food'!$C:$C,'Hiker Food'!W:W))}
B14: Recovery | C14: Tailwind Nutrition Chocolate Recovery | D14: 1 | E14: {=if(C14="","",_xlfn.xlookup(C14,'Hiker Food'!$C:$C,'Hiker Food'!G:G)*D14)} -> 2 | F14: {=if(C14="","",_xlfn.xlookup(C14,'Hiker Food'!$C:$C,'Hiker Food'!H:H)*D14)} -> 60 | G14: {=if($C14="","",_xlfn.xlookup($C14,'Hiker Food'!$C:$C,'Hiker Food'!J:J)*$D14)} -> 0 | H14: {=if($C14="","",_xlfn.xlookup($C14,'Hiker Food'!$C:$C,'Hiker Food'!K:K)*$D14)} -> 500 | I14: {=if($C14="","",_xlfn.xlookup($C14,'Hiker Food'!$C:$C,'Hiker Food'!L:L)*$D14)} -> 470 | J14: {=if($C14="","",_xlfn.xlookup($C14,'Hiker Food'!$C:$C,'Hiker Food'!M:M)*$D14)} -> 34 | K14: {=if($C14="","",_xlfn.xlookup($C14,'Hiker Food'!$C:$C,'Hiker Food'!N:N)*$D14)} -> 1 | L14: {=if($C14="","",_xlfn.xlookup($C14,'Hiker Food'!$C:$C,'Hiker Food'!O:O)*$D14)} -> 32 | M14: {=if($C14="","",_xlfn.xlookup($C14,'Hiker Food'!$C:$C,'Hiker Food'!P:P)*$D14)} -> 1 | N14: {=if($C14="","",_xlfn.xlookup($C14,'Hiker Food'!$C:$C,'Hiker Food'!Q:Q)*$D14)} -> 20 | O14: {=if($C14="","",_xlfn.xlookup($C14,'Hiker Food'!$C:$C,'Hiker Food'!I:I)*$D14)} -> 220 | P14: {=if($C14="","",_xlfn.xlookup($C14,'Hiker Food'!$C:$C,'Hiker Food'!T:T))} -> 1.7 | Q14: {=if($C14="","",_xlfn.xlookup($C14,'Hiker Food'!$C:$C,'Hiker Food'!U:U))} -> 0% | R14: {=if($C14="","",_xlfn.xlookup($C14,'Hiker Food'!$C:$C,'Hiker Food'!V:V))} -> 0.59259259 | S14: {=if($C14="","",_xlfn.xlookup($C14,'Hiker Food'!$C:$C,'Hiker Food'!W:W))} -> 2.2727273 | T14: Recovery | U14: =if(C14="","",Y14/V14) -> 110 | V14: =if($C14="","",sum(E14:E16)) -> 2 | W14: =if($C14="","",$Y14/X14) -> 3.6666667 | X14: =if($C14="","",sum(F14:F16)) -> 60 | Y14: =if($C14="","",sum(O14:O16)) -> 220 | Z14: =if($C14="","",(sum(J14:J16)/sum(N14:N16))) -> 1.7 | AA14: =if($C14="","",sum(G14:G16)*9/sum(sum(G14:G16)*9+sum(J14:J16)*4+sum(N14:N16)*4)) -> 0 | AB14: =if($C14="","",sum(L14:L16)*4/sum(sum(G14:G16)*9+sum(J14:J16)*4+sum(N14:N16)*4)) -> 0.59259259 | AC14: =if($C14="","",(sum(H14:H16)/sum(O14:O16))) -> 2.2727273
D15: 1 | E15: {=if(C15="","",_xlfn.xlookup(C15,'Hiker Food'!$C:$C,'Hiker Food'!G:G)*D15)} | F15: {=if(C15="","",_xlfn.xlookup(C15,'Hiker Food'!$C:$C,'Hiker Food'!H:H)*D15)} | G15: {=if($C15="","",_xlfn.xlookup($C15,'Hiker Food'!$C:$C,'Hiker Food'!J:J)*$D15)} | H15: {=if($C15="","",_xlfn.xlookup($C15,'Hiker Food'!$C:$C,'Hiker Food'!K:K)*$D15)} | I15: {=if($C15="","",_xlfn.xlookup($C15,'Hiker Food'!$C:$C,'Hiker Food'!L:L)*$D15)} | J15: {=if($C15="","",_xlfn.xlookup($C15,'Hiker Food'!$C:$C,'Hiker Food'!M:M)*$D15)} | K15: {=if($C15="","",_xlfn.xlookup($C15,'Hiker Food'!$C:$C,'Hiker Food'!N:N)*$D15)} | L15: {=if($C15="","",_xlfn.xlookup($C15,'Hiker Food'!$C:$C,'Hiker Food'!O:O)*$D15)} | M15: {=if($C15="","",_xlfn.xlookup($C15,'Hiker Food'!$C:$C,'Hiker Food'!P:P)*$D15)} | N15: {=if($C15="","",_xlfn.xlookup($C15,'Hiker Food'!$C:$C,'Hiker Food'!Q:Q)*$D15)} | O15: {=if($C15="","",_xlfn.xlookup($C15,'Hiker Food'!$C:$C,'Hiker Food'!I:I)*$D15)} | P15: {=if($C15="","",_xlfn.xlookup($C15,'Hiker Food'!$C:$C,'Hiker Food'!T:T))} | Q15: {=if($C15="","",_xlfn.xlookup($C15,'Hiker Food'!$C:$C,'Hiker Food'!U:U))} | R15: {=if($C15="","",_xlfn.xlookup($C15,'Hiker Food'!$C:$C,'Hiker Food'!V:V))} | S15: {=if($C15="","",_xlfn.xlookup($C15,'Hiker Food'!$C:$C,'Hiker Food'!W:W))}
D16: 1 | E16: {=if(C16="","",_xlfn.xlookup(C16,'Hiker Food'!$C:$C,'Hiker Food'!G:G)*D16)} | F16: {=if(C16="","",_xlfn.xlookup(C16,'Hiker Food'!$C:$C,'Hiker Food'!H:H)*D16)} | G16: {=if($C16="","",_xlfn.xlookup($C16,'Hiker Food'!$C:$C,'Hiker Food'!J:J)*$D16)} | H16: {=if($C16="","",_xlfn.xlookup($C16,'Hiker Food'!$C:$C,'Hiker Food'!K:K)*$D16)} | I16: {=if($C16="","",_xlfn.xlookup($C16,'Hiker Food'!$C:$C,'Hiker Food'!L:L)*$D16)} | J16: {=if($C16="","",_xlfn.xlookup($C16,'Hiker Food'!$C:$C,'Hiker Food'!M:M)*$D16)} | K16: {=if($C16="","",_xlfn.xlookup($C16,'Hiker Food'!$C:$C,'Hiker Food'!N:N)*$D16)} | L16: {=if($C16="","",_xlfn.xlookup($C16,'Hiker Food'!$C:$C,'Hiker Food'!O:O)*$D16)} | M16: {=if($C16="","",_xlfn.xlookup($C16,'Hiker Food'!$C:$C,'Hiker Food'!P:P)*$D16)} | N16: {=if($C16="","",_xlfn.xlookup($C16,'Hiker Food'!$C:$C,'Hiker Food'!Q:Q)*$D16)} | O16: {=if($C16="","",_xlfn.xlookup($C16,'Hiker Food'!$C:$C,'Hiker Food'!I:I)*$D16)} | P16: {=if($C16="","",_xlfn.xlookup($C16,'Hiker Food'!$C:$C,'Hiker Food'!T:T))} | Q16: {=if($C16="","",_xlfn.xlookup($C16,'Hiker Food'!$C:$C,'Hiker Food'!U:U))} | R16: {=if($C16="","",_xlfn.xlookup($C16,'Hiker Food'!$C:$C,'Hiker Food'!V:V))} | S16: {=if($C16="","",_xlfn.xlookup($C16,'Hiker Food'!$C:$C,'Hiker Food'!W:W))}
B17: Dinner | C17: Pinnacle Foods Thai Peanut Curry, Roasted Vegetables, Rice Noodles | D17: 1 | E17: {=if(C17="","",_xlfn.xlookup(C17,'Hiker Food'!$C:$C,'Hiker Food'!G:G)*D17)} -> 3.809591 | F17: {=if(C17="","",_xlfn.xlookup(C17,'Hiker Food'!$C:$C,'Hiker Food'!H:H)*D17)} -> 108 | G17: {=if($C17="","",_xlfn.xlookup($C17,'Hiker Food'!$C:$C,'Hiker Food'!J:J)*$D17)} -> 37 | H17: {=if($C17="","",_xlfn.xlookup($C17,'Hiker Food'!$C:$C,'Hiker Food'!K:K)*$D17)} -> 930 | I17: {=if($C17="","",_xlfn.xlookup($C17,'Hiker Food'!$C:$C,'Hiker Food'!L:L)*$D17)} -> 540 | J17: {=if($C17="","",_xlfn.xlookup($C17,'Hiker Food'!$C:$C,'Hiker Food'!M:M)*$D17)} -> 53 | K17: {=if($C17="","",_xlfn.xlookup($C17,'Hiker Food'!$C:$C,'Hiker Food'!N:N)*$D17)} -> 10 | L17: {=if($C17="","",_xlfn.xlookup($C17,'Hiker Food'!$C:$C,'Hiker Food'!O:O)*$D17)} -> 13 | M17: {=if($C17="","",_xlfn.xlookup($C17,'Hiker Food'!$C:$C,'Hiker Food'!P:P)*$D17)} -> 30 | N17: {=if($C17="","",_xlfn.xlookup($C17,'Hiker Food'!$C:$C,'Hiker Food'!Q:Q)*$D17)} -> 20 | O17: {=if($C17="","",_xlfn.xlookup($C17,'Hiker Food'!$C:$C,'Hiker Food'!I:I)*$D17)} -> 630 | P17: {=if($C17="","",_xlfn.xlookup($C17,'Hiker Food'!$C:$C,'Hiker Food'!T:T))} -> 2.65 | Q17: {=if($C17="","",_xlfn.xlookup($C17,'Hiker Food'!$C:$C,'Hiker Food'!U:U))} -> 0.5328 | R17: {=if($C17="","",_xlfn.xlookup($C17,'Hiker Food'!$C:$C,'Hiker Food'!V:V))} -> 0.0832 | S17: {=if($C17="","",_xlfn.xlookup($C17,'Hiker Food'!$C:$C,'Hiker Food'!W:W))} -> 1.4761905 | T17: Dinner | U17: =if(C17="","",Y17/V17) -> 165.37208 | V17: =if($C17="","",sum(E17:E19)) -> 3.809591 | W17: =if($C17="","",$Y17/X17) -> 5.8333333 | X17: =if($C17="","",sum(F17:F19)) -> 108 | Y17: =if($C17="","",sum(O17:O19)) -> 630 | Z17: =if($C17="","",(sum(J17:J19)/sum(N17:N19))) -> 2.65 | AA17: =if($C17="","",sum(G17:G19)*9/sum(sum(G17:G19)*9+sum(J17:J19)*4+sum(N17:N19)*4)) -> 0.5328 | AB17: =if($C17="","",sum(L17:L19)*4/sum(sum(G17:G19)*9+sum(J17:J19)*4+sum(N17:N19)*4)) -> 0.0832 | AC17: =if($C17="","",(sum(H17:H19)/sum(O17:O19))) -> 1.4761905
D18: 1 | E18: {=if(C18="","",_xlfn.xlookup(C18,'Hiker Food'!$C:$C,'Hiker Food'!G:G)*D18)} | F18: {=if(C18="","",_xlfn.xlookup(C18,'Hiker Food'!$C:$C,'Hiker Food'!H:H)*D18)} | G18: {=if($C18="","",_xlfn.xlookup($C18,'Hiker Food'!$C:$C,'Hiker Food'!J:J)*$D18)} | H18: {=if($C18="","",_xlfn.xlookup($C18,'Hiker Food'!$C:$C,'Hiker Food'!K:K)*$D18)} | I18: {=if($C18="","",_xlfn.xlookup($C18,'Hiker Food'!$C:$C,'Hiker Food'!L:L)*$D18)} | J18: {=if($C18="","",_xlfn.xlookup($C18,'Hiker Food'!$C:$C,'Hiker Food'!M:M)*$D18)} | K18: {=if($C18="","",_xlfn.xlookup($C18,'Hiker Food'!$C:$C,'Hiker Food'!N:N)*$D18)} | L18: {=if($C18="","",_xlfn.xlookup($C18,'Hiker Food'!$C:$C,'Hiker Food'!O:O)*$D18)} | M18: {=if($C18="","",_xlfn.xlookup($C18,'Hiker Food'!$C:$C,'Hiker Food'!P:P)*$D18)} | N18: {=if($C18="","",_xlfn.xlookup($C18,'Hiker Food'!$C:$C,'Hiker Food'!Q:Q)*$D18)} | O18: {=if($C18="","",_xlfn.xlookup($C18,'Hiker Food'!$C:$C,'Hiker Food'!I:I)*$D18)} | P18: {=if($C18="","",_xlfn.xlookup($C18,'Hiker Food'!$C:$C,'Hiker Food'!T:T))} | Q18: {=if($C18="","",_xlfn.xlookup($C18,'Hiker Food'!$C:$C,'Hiker Food'!U:U))} | R18: {=if($C18="","",_xlfn.xlookup($C18,'Hiker Food'!$C:$C,'Hiker Food'!V:V))} | S18: {=if($C18="","",_xlfn.xlookup($C18,'Hiker Food'!$C:$C,'Hiker Food'!W:W))}
D19: 1 | E19: {=if(C19="","",_xlfn.xlookup(C19,'Hiker Food'!$C:$C,'Hiker Food'!G:G)*D19)} | F19: {=if(C19="","",_xlfn.xlookup(C19,'Hiker Food'!$C:$C,'Hiker Food'!H:H)*D19)} | G19: {=if($C19="","",_xlfn.xlookup($C19,'Hiker Food'!$C:$C,'Hiker Food'!J:J)*$D19)} | H19: {=if($C19="","",_xlfn.xlookup($C19,'Hiker Food'!$C:$C,'Hiker Food'!K:K)*$D19)} | I19: {=if($C19="","",_xlfn.xlookup($C19,'Hiker Food'!$C:$C,'Hiker Food'!L:L)*$D19)} | J19: {=if($C19="","",_xlfn.xlookup($C19,'Hiker Food'!$C:$C,'Hiker Food'!M:M)*$D19)} | K19: {=if($C19="","",_xlfn.xlookup($C19,'Hiker Food'!$C:$C,'Hiker Food'!N:N)*$D19)} | L19: {=if($C19="","",_xlfn.xlookup($C19,'Hiker Food'!$C:$C,'Hiker Food'!O:O)*$D19)} | M19: {=if($C19="","",_xlfn.xlookup($C19,'Hiker Food'!$C:$C,'Hiker Food'!P:P)*$D19)} | N19: {=if($C19="","",_xlfn.xlookup($C19,'Hiker Food'!$C:$C,'Hiker Food'!Q:Q)*$D19)} | O19: {=if($C19="","",_xlfn.xlookup($C19,'Hiker Food'!$C:$C,'Hiker Food'!I:I)*$D19)} | P19: {=if($C19="","",_xlfn.xlookup($C19,'Hiker Food'!$C:$C,'Hiker Food'!T:T))} | Q19: {=if($C19="","",_xlfn.xlookup($C19,'Hiker Food'!$C:$C,'Hiker Food'!U:U))} | R19: {=if($C19="","",_xlfn.xlookup($C19,'Hiker Food'!$C:$C,'Hiker Food'!V:V))} | S19: {=if($C19="","",_xlfn.xlookup($C19,'Hiker Food'!$C:$C,'Hiker Food'!W:W))}
B20: Dessert | D20: 1 | E20: {=if(C20="","",_xlfn.xlookup(C20,'Hiker Food'!$C:$C,'Hiker Food'!G:G)*D20)} | F20: {=if(C20="","",_xlfn.xlookup(C20,'Hiker Food'!$C:$C,'Hiker Food'!H:H)*D20)} | G20: {=if($C20="","",_xlfn.xlookup($C20,'Hiker Food'!$C:$C,'Hiker Food'!J:J)*$D20)} | H20: {=if($C20="","",_xlfn.xlookup($C20,'Hiker Food'!$C:$C,'Hiker Food'!K:K)*$D20)} | I20: {=if($C20="","",_xlfn.xlookup($C20,'Hiker Food'!$C:$C,'Hiker Food'!L:L)*$D20)} | J20: {=if($C20="","",_xlfn.xlookup($C20,'Hiker Food'!$C:$C,'Hiker Food'!M:M)*$D20)} | K20: {=if($C20="","",_xlfn.xlookup($C20,'Hiker Food'!$C:$C,'Hiker Food'!N:N)*$D20)} | L20: {=if($C20="","",_xlfn.xlookup($C20,'Hiker Food'!$C:$C,'Hiker Food'!O:O)*$D20)} | M20: {=if($C20="","",_xlfn.xlookup($C20,'Hiker Food'!$C:$C,'Hiker Food'!P:P)*$D20)} | N20: {=if($C20="","",_xlfn.xlookup($C20,'Hiker Food'!$C:$C,'Hiker Food'!Q:Q)*$D20)} | O20: {=if($C20="","",_xlfn.xlookup($C20,'Hiker Food'!$C:$C,'Hiker Food'!I:I)*$D20)} | P20: {=if($C20="","",_xlfn.xlookup($C20,'Hiker Food'!$C:$C,'Hiker Food'!T:T))} | Q20: {=if($C20="","",_xlfn.xlookup($C20,'Hiker Food'!$C:$C,'Hiker Food'!U:U))} | R20: {=if($C20="","",_xlfn.xlookup($C20,'Hiker Food'!$C:$C,'Hiker Food'!V:V))} | S20: {=if($C20="","",_xlfn.xlookup($C20,'Hiker Food'!$C:$C,'Hiker Food'!W:W))} | T20: Dessert | U20: =if(C20="","",Y20/V20) | V20: =if($C20="","",sum(E20:E22)) | W20: =if($C20="","",$Y20/X20) | X20: =if($C20="","",sum(F20:F22)) | Y20: =if($C20="","",sum(O20:O22)) | Z20: =if($C20="","",(sum(J20:J22)/sum(N20:N22))) | AA20: =if($C20="","",sum(G20:G22)*9/sum(sum(G20:G22)*9+sum(J20:J22)*4+sum(N20:N22)*4)) | AB20: =if($C20="","",sum(L20:L22)*4/sum(sum(G20:G22)*9+sum(J20:J22)*4+sum(N20:N22)*4)) | AC20: =if($C20="","",(sum(H20:H22)/sum(O20:O22)))
D21: 1 | E21: {=if(C21="","",_xlfn.xlookup(C21,'Hiker Food'!$C:$C,'Hiker Food'!G:G)*D21)} | F21: {=if(C21="","",_xlfn.xlookup(C21,'Hiker Food'!$C:$C,'Hiker Food'!H:H)*D21)} | G21: {=if($C21="","",_xlfn.xlookup($C21,'Hiker Food'!$C:$C,'Hiker Food'!J:J)*$D21)} | H21: {=if($C21="","",_xlfn.xlookup($C21,'Hiker Food'!$C:$C,'Hiker Food'!K:K)*$D21)} | I21: {=if($C21="","",_xlfn.xlookup($C21,'Hiker Food'!$C:$C,'Hiker Food'!L:L)*$D21)} | J21: {=if($C21="","",_xlfn.xlookup($C21,'Hiker Food'!$C:$C,'Hiker Food'!M:M)*$D21)} | K21: {=if($C21="","",_xlfn.xlookup($C21,'Hiker Food'!$C:$C,'Hiker Food'!N:N)*$D21)} | L21: {=if($C21="","",_xlfn.xlookup($C21,'Hiker Food'!$C:$C,'Hiker Food'!O:O)*$D21)} | M21: {=if($C21="","",_xlfn.xlookup($C21,'Hiker Food'!$C:$C,'Hiker Food'!P:P)*$D21)} | N21: {=if($C21="","",_xlfn.xlookup($C21,'Hiker Food'!$C:$C,'Hiker Food'!Q:Q)*$D21)} | O21: {=if($C21="","",_xlfn.xlookup($C21,'Hiker Food'!$C:$C,'Hiker Food'!I:I)*$D21)} | P21: {=if($C21="","",_xlfn.xlookup($C21,'Hiker Food'!$C:$C,'Hiker Food'!T:T))} | Q21: {=if($C21="","",_xlfn.xlookup($C21,'Hiker Food'!$C:$C,'Hiker Food'!U:U))} | R21: {=if($C21="","",_xlfn.xlookup($C21,'Hiker Food'!$C:$C,'Hiker Food'!V:V))} | S21: {=if($C21="","",_xlfn.xlookup($C21,'Hiker Food'!$C:$C,'Hiker Food'!W:W))}
D22: 1 | E22: {=if(C22="","",_xlfn.xlookup(C22,'Hiker Food'!$C:$C,'Hiker Food'!G:G)*D22)} | F22: {=if(C22="","",_xlfn.xlookup(C22,'Hiker Food'!$C:$C,'Hiker Food'!H:H)*D22)} | G22: {=if($C22="","",_xlfn.xlookup($C22,'Hiker Food'!$C:$C,'Hiker Food'!J:J)*$D22)} | H22: {=if($C22="","",_xlfn.xlookup($C22,'Hiker Food'!$C:$C,'Hiker Food'!K:K)*$D22)} | I22: {=if($C22="","",_xlfn.xlookup($C22,'Hiker Food'!$C:$C,'Hiker Food'!L:L)*$D22)} | J22: {=if($C22="","",_xlfn.xlookup($C22,'Hiker Food'!$C:$C,'Hiker Food'!M:M)*$D22)} | K22: {=if($C22="","",_xlfn.xlookup($C22,'Hiker Food'!$C:$C,'Hiker Food'!N:N)*$D22)} | L22: {=if($C22="","",_xlfn.xlookup($C22,'Hiker Food'!$C:$C,'Hiker Food'!O:O)*$D22)} | M22: {=if($C22="","",_xlfn.xlookup($C22,'Hiker Food'!$C:$C,'Hiker Food'!P:P)*$D22)} | N22: {=if($C22="","",_xlfn.xlookup($C22,'Hiker Food'!$C:$C,'Hiker Food'!Q:Q)*$D22)} | O22: {=if($C22="","",_xlfn.xlookup($C22,'Hiker Food'!$C:$C,'Hiker Food'!I:I)*$D22)} | P22: {=if($C22="","",_xlfn.xlookup($C22,'Hiker Food'!$C:$C,'Hiker Food'!T:T))} | Q22: {=if($C22="","",_xlfn.xlookup($C22,'Hiker Food'!$C:$C,'Hiker Food'!U:U))} | R22: {=if($C22="","",_xlfn.xlookup($C22,'Hiker Food'!$C:$C,'Hiker Food'!V:V))} | S22: {=if($C22="","",_xlfn.xlookup($C22,'Hiker Food'!$C:$C,'Hiker Food'!W:W))}
B23: Total | C23: =IF(COUNTIF(C2:C22,"")=COUNTA(C2:C22), "", "zzzz - subtotal line - ignore") -> zzzz - subtotal line - ignore | E23: =if(counta($C2:$C22)=0,"",SUM(E2:E22)) -> 22.95275 | F23: =if(counta($C2:$C22)=0,"",SUM(F2:F22)) -> 654 | G23: =if(counta($C2:$C22)=0,"",SUM(G2:G22)) -> 195 | H23: =if(counta($C2:$C22)=0,"",SUM(H2:H22)) -> 3807 | I23: =if(counta($C2:$C22)=0,"",SUM(I2:I22)) -> 1390 | J23: =if(counta($C2:$C22)=0,"",SUM(J2:J22)) -> 254 | K23: =if(counta($C2:$C22)=0,"",SUM(K2:K22)) -> 32 | L23: =if(counta($C2:$C22)=0,"",SUM(L2:L22)) -> 122 | ... O23: =if(counta($C2:$C22)=0,"",SUM(O2:O22)) -> 3170 | T23: Total | V23: =if(counta($C2:$C22)=0,"",SUM(E2:E22)) -> 22.95275 | X23: =if(counta($C2:$C22)=0,"",SUM(F2:F22)) -> 654 | Y23: =if(counta($C2:$C22)=0,"",SUM(O2:O22)) -> 3170 | Z23: =if($V23="","",sum(J2:J22)/sum(N2:N22)) -> 2.1896552 | AA23: =if($V23="","",sum(G2:G22)*9/sum(sum(G2:G22)*9+sum(J2:J22)*4+sum(N2:N22)*4)) -> 0.54250386 | AB23: =if($V23="","",sum(L2:L22)*4/sum(sum(G2:G22)*9+sum(J2:J22)*4+sum(N2:N22)*4)) -> 0.15085008 | AC23: =if($V23="","",sum(H2:H22)/sum(O2:O22)) -> 1.2009464
A24: 2 | B24: Breakfast | D24: 1 | E24: {=if(C24="","",_xlfn.xlookup(C24,'Hiker Food'!$C:$C,'Hiker Food'!G:G)*D24)} | F24: {=if(C24="","",_xlfn.xlookup(C24,'Hiker Food'!$C:$C,'Hiker Food'!H:H)*D24)} | G24: {=if($C24="","",_xlfn.xlookup($C24,'Hiker Food'!$C:$C,'Hiker Food'!J:J)*$D24)} | H24: {=if($C24="","",_xlfn.xlookup($C24,'Hiker Food'!$C:$C,'Hiker Food'!K:K)*$D24)} | I24: {=if($C24="","",_xlfn.xlookup($C24,'Hiker Food'!$C:$C,'Hiker Food'!L:L)*$D24)} | J24: {=if($C24="","",_xlfn.xlookup($C24,'Hiker Food'!$C:$C,'Hiker Food'!M:M)*$D24)} | K24: {=if($C24="","",_xlfn.xlookup($C24,'Hiker Food'!$C:$C,'Hiker Food'!N:N)*$D24)} | L24: {=if($C24="","",_xlfn.xlookup($C24,'Hiker Food'!$C:$C,'Hiker Food'!O:O)*$D24)} | M24: {=if($C24="","",_xlfn.xlookup($C24,'Hiker Food'!$C:$C,'Hiker Food'!P:P)*$D24)} | N24: {=if($C24="","",_xlfn.xlookup($C24,'Hiker Food'!$C:$C,'Hiker Food'!Q:Q)*$D24)} | O24: {=if($C24="","",_xlfn.xlookup($C24,'Hiker Food'!$C:$C,'Hiker Food'!I:I)*$D24)} | P24: {=if($C24="","",_xlfn.xlookup($C24,'Hiker Food'!$C:$C,'Hiker Food'!T:T))} | Q24: {=if($C24="","",_xlfn.xlookup($C24,'Hiker Food'!$C:$C,'Hiker Food'!U:U))} | R24: {=if($C24="","",_xlfn.xlookup($C24,'Hiker Food'!$C:$C,'Hiker Food'!V:V))} | S24: {=if($C24="","",_xlfn.xlookup($C24,'Hiker Food'!$C:$C,'Hiker Food'!W:W))} | T24: Breakfast | U24: =if($C24="","",$Y24/V24) | V24: =if($C24="","",sum(E24:E26)) | W24: =if($C24="","",$Y24/X24) | X24: =if($C24="","",sum(F24:F26)) | Y24: =if($C24="","",sum(O24:O26)) | Z24: =if($C24="","",(sum(J24:J26)/sum(N24:N26))) | AA24: =if($C24="","",sum(G24:G26)*9/sum(sum(G24:G26)*9+sum(J24:J26)*4+sum(N24:N26)*4)) | AB24: =if($C24="","",sum(L24:L26)*4/sum(sum(G24:G26)*9+sum(J24:J26)*4+sum(N24:N26)*4)) | AC24: =if($C24="","",(sum(H24:H26)/sum(O24:O26)))
D25: 1 | E25: {=if(C25="","",_xlfn.xlookup(C25,'Hiker Food'!$C:$C,'Hiker Food'!G:G)*D25)} | F25: {=if(C25="","",_xlfn.xlookup(C25,'Hiker Food'!$C:$C,'Hiker Food'!H:H)*D25)} | G25: {=if($C25="","",_xlfn.xlookup($C25,'Hiker Food'!$C:$C,'Hiker Food'!J:J)*$D25)} | H25: {=if($C25="","",_xlfn.xlookup($C25,'Hiker Food'!$C:$C,'Hiker Food'!K:K)*$D25)} | I25: {=if($C25="","",_xlfn.xlookup($C25,'Hiker Food'!$C:$C,'Hiker Food'!L:L)*$D25)} | J25: {=if($C25="","",_xlfn.xlookup($C25,'Hiker Food'!$C:$C,'Hiker Food'!M:M)*$D25)} | K25: {=if($C25="","",_xlfn.xlookup($C25,'Hiker Food'!$C:$C,'Hiker Food'!N:N)*$D25)} | L25: {=if($C25="","",_xlfn.xlookup($C25,'Hiker Food'!$C:$C,'Hiker Food'!O:O)*$D25)} | M25: {=if($C25="","",_xlfn.xlookup($C25,'Hiker Food'!$C:$C,'Hiker Food'!P:P)*$D25)} | N25: {=if($C25="","",_xlfn.xlookup($C25,'Hiker Food'!$C:$C,'Hiker Food'!Q:Q)*$D25)} | O25: {=if($C25="","",_xlfn.xlookup($C25,'Hiker Food'!$C:$C,'Hiker Food'!I:I)*$D25)} | P25: {=if($C25="","",_xlfn.xlookup($C25,'Hiker Food'!$C:$C,'Hiker Food'!T:T))} | Q25: {=if($C25="","",_xlfn.xlookup($C25,'Hiker Food'!$C:$C,'Hiker Food'!U:U))} | R25: {=if($C25="","",_xlfn.xlookup($C25,'Hiker Food'!$C:$C,'Hiker Food'!V:V))} | S25: {=if($C25="","",_xlfn.xlookup($C25,'Hiker Food'!$C:$C,'Hiker Food'!W:W))}
D26: 1 | E26: {=if(C26="","",_xlfn.xlookup(C26,'Hiker Food'!$C:$C,'Hiker Food'!G:G)*D26)} | F26: {=if(C26="","",_xlfn.xlookup(C26,'Hiker Food'!$C:$C,'Hiker Food'!H:H)*D26)} | G26: {=if($C26="","",_xlfn.xlookup($C26,'Hiker Food'!$C:$C,'Hiker Food'!J:J)*$D26)} | H26: {=if($C26="","",_xlfn.xlookup($C26,'Hiker Food'!$C:$C,'Hiker Food'!K:K)*$D26)} | I26: {=if($C26="","",_xlfn.xlookup($C26,'Hiker Food'!$C:$C,'Hiker Food'!L:L)*$D26)} | J26: {=if($C26="","",_xlfn.xlookup($C26,'Hiker Food'!$C:$C,'Hiker Food'!M:M)*$D26)} | K26: {=if($C26="","",_xlfn.xlookup($C26,'Hiker Food'!$C:$C,'Hiker Food'!N:N)*$D26)} | L26: {=if($C26="","",_xlfn.xlookup($C26,'Hiker Food'!$C:$C,'Hiker Food'!O:O)*$D26)} | M26: {=if($C26="","",_xlfn.xlookup($C26,'Hiker Food'!$C:$C,'Hiker Food'!P:P)*$D26)} | N26: {=if($C26="","",_xlfn.xlookup($C26,'Hiker Food'!$C:$C,'Hiker Food'!Q:Q)*$D26)} | O26: {=if($C26="","",_xlfn.xlookup($C26,'Hiker Food'!$C:$C,'Hiker Food'!I:I)*$D26)} | P26: {=if($C26="","",_xlfn.xlookup($C26,'Hiker Food'!$C:$C,'Hiker Food'!T:T))} | Q26: {=if($C26="","",_xlfn.xlookup($C26,'Hiker Food'!$C:$C,'Hiker Food'!U:U))} | R26: {=if($C26="","",_xlfn.xlookup($C26,'Hiker Food'!$C:$C,'Hiker Food'!V:V))} | S26: {=if($C26="","",_xlfn.xlookup($C26,'Hiker Food'!$C:$C,'Hiker Food'!W:W))}
B27: Morning Snacks | D27: 2 | E27: {=if(C27="","",_xlfn.xlookup(C27,'Hiker Food'!$C:$C,'Hiker Food'!G:G)*D27)} | F27: {=if(C27="","",_xlfn.xlookup(C27,'Hiker Food'!$C:$C,'Hiker Food'!H:H)*D27)} | G27: {=if($C27="","",_xlfn.xlookup($C27,'Hiker Food'!$C:$C,'Hiker Food'!J:J)*$D27)} | H27: {=if($C27="","",_xlfn.xlookup($C27,'Hiker Food'!$C:$C,'Hiker Food'!K:K)*$D27)} | I27: {=if($C27="","",_xlfn.xlookup($C27,'Hiker Food'!$C:$C,'Hiker Food'!L:L)*$D27)} | J27: {=if($C27="","",_xlfn.xlookup($C27,'Hiker Food'!$C:$C,'Hiker Food'!M:M)*$D27)} | K27: {=if($C27="","",_xlfn.xlookup($C27,'Hiker Food'!$C:$C,'Hiker Food'!N:N)*$D27)} | L27: {=if($C27="","",_xlfn.xlookup($C27,'Hiker Food'!$C:$C,'Hiker Food'!O:O)*$D27)} | M27: {=if($C27="","",_xlfn.xlookup($C27,'Hiker Food'!$C:$C,'Hiker Food'!P:P)*$D27)} | N27: {=if($C27="","",_xlfn.xlookup($C27,'Hiker Food'!$C:$C,'Hiker Food'!Q:Q)*$D27)} | O27: {=if($C27="","",_xlfn.xlookup($C27,'Hiker Food'!$C:$C,'Hiker Food'!I:I)*$D27)} | P27: {=if($C27="","",_xlfn.xlookup($C27,'Hiker Food'!$C:$C,'Hiker Food'!T:T))} | Q27: {=if($C27="","",_xlfn.xlookup($C27,'Hiker Food'!$C:$C,'Hiker Food'!U:U))} | R27: {=if($C27="","",_xlfn.xlookup($C27,'Hiker Food'!$C:$C,'Hiker Food'!V:V))} | S27: {=if($C27="","",_xlfn.xlookup($C27,'Hiker Food'!$C:$C,'Hiker Food'!W:W))} | T27: Morning Snacks | U27: =if(C27="","",Y27/V27) | V27: =if($C27="","",sum(E27:E29)) | W27: =if($C27="","",$Y27/X27) | X27: =if($C27="","",sum(F27:F29)) | Y27: =if($C27="","",sum(O27:O29)) | Z27: =if($C27="","",(sum(J27:J29)/sum(N27:N29))) | AA27: =if($C27="","",sum(G27:G29)*9/sum(sum(G27:G29)*9+sum(J27:J29)*4+sum(N27:N29)*4)) | AB27: =if($C27="","",sum(L27:L29)*4/sum(sum(G27:G29)*9+sum(J27:J29)*4+sum(N27:N29)*4)) | AC27: =if($C27="","",(sum(H27:H29)/sum(O27:O29)))
D28: 2 | E28: {=if(C28="","",_xlfn.xlookup(C28,'Hiker Food'!$C:$C,'Hiker Food'!G:G)*D28)} | F28: {=if(C28="","",_xlfn.xlookup(C28,'Hiker Food'!$C:$C,'Hiker Food'!H:H)*D28)} | G28: {=if($C28="","",_xlfn.xlookup($C28,'Hiker Food'!$C:$C,'Hiker Food'!J:J)*$D28)} | H28: {=if($C28="","",_xlfn.xlookup($C28,'Hiker Food'!$C:$C,'Hiker Food'!K:K)*$D28)} | I28: {=if($C28="","",_xlfn.xlookup($C28,'Hiker Food'!$C:$C,'Hiker Food'!L:L)*$D28)} | J28: {=if($C28="","",_xlfn.xlookup($C28,'Hiker Food'!$C:$C,'Hiker Food'!M:M)*$D28)} | K28: {=if($C28="","",_xlfn.xlookup($C28,'Hiker Food'!$C:$C,'Hiker Food'!N:N)*$D28)} | L28: {=if($C28="","",_xlfn.xlookup($C28,'Hiker Food'!$C:$C,'Hiker Food'!O:O)*$D28)} | M28: {=if($C28="","",_xlfn.xlookup($C28,'Hiker Food'!$C:$C,'Hiker Food'!P:P)*$D28)} | N28: {=if($C28="","",_xlfn.xlookup($C28,'Hiker Food'!$C:$C,'Hiker Food'!Q:Q)*$D28)} | O28: {=if($C28="","",_xlfn.xlookup($C28,'Hiker Food'!$C:$C,'Hiker Food'!I:I)*$D28)} | P28: {=if($C28="","",_xlfn.xlookup($C28,'Hiker Food'!$C:$C,'Hiker Food'!T:T))} | Q28: {=if($C28="","",_xlfn.xlookup($C28,'Hiker Food'!$C:$C,'Hiker Food'!U:U))} | R28: {=if($C28="","",_xlfn.xlookup($C28,'Hiker Food'!$C:$C,'Hiker Food'!V:V))} | S28: {=if($C28="","",_xlfn.xlookup($C28,'Hiker Food'!$C:$C,'Hiker Food'!W:W))}
D29: 1 | E29: {=if(C29="","",_xlfn.xlookup(C29,'Hiker Food'!$C:$C,'Hiker Food'!G:G)*D29)} | F29: {=if(C29="","",_xlfn.xlookup(C29,'Hiker Food'!$C:$C,'Hiker Food'!H:H)*D29)} | G29: {=if($C29="","",_xlfn.xlookup($C29,'Hiker Food'!$C:$C,'Hiker Food'!J:J)*$D29)} | H29: {=if($C29="","",_xlfn.xlookup($C29,'Hiker Food'!$C:$C,'Hiker Food'!K:K)*$D29)} | I29: {=if($C29="","",_xlfn.xlookup($C29,'Hiker Food'!$C:$C,'Hiker Food'!L:L)*$D29)} | J29: {=if($C29="","",_xlfn.xlookup($C29,'Hiker Food'!$C:$C,'Hiker Food'!M:M)*$D29)} | K29: {=if($C29="","",_xlfn.xlookup($C29,'Hiker Food'!$C:$C,'Hiker Food'!N:N)*$D29)} | L29: {=if($C29="","",_xlfn.xlookup($C29,'Hiker Food'!$C:$C,'Hiker Food'!O:O)*$D29)} | M29: {=if($C29="","",_xlfn.xlookup($C29,'Hiker Food'!$C:$C,'Hiker Food'!P:P)*$D29)} | N29: {=if($C29="","",_xlfn.xlookup($C29,'Hiker Food'!$C:$C,'Hiker Food'!Q:Q)*$D29)} | O29: {=if($C29="","",_xlfn.xlookup($C29,'Hiker Food'!$C:$C,'Hiker Food'!I:I)*$D29)} | P29: {=if($C29="","",_xlfn.xlookup($C29,'Hiker Food'!$C:$C,'Hiker Food'!T:T))} | Q29: {=if($C29="","",_xlfn.xlookup($C29,'Hiker Food'!$C:$C,'Hiker Food'!U:U))} | R29: {=if($C29="","",_xlfn.xlookup($C29,'Hiker Food'!$C:$C,'Hiker Food'!V:V))} | S29: {=if($C29="","",_xlfn.xlookup($C29,'Hiker Food'!$C:$C,'Hiker Food'!W:W))}
B30: Lunch | D30: 3 | E30: {=if(C30="","",_xlfn.xlookup(C30,'Hiker Food'!$C:$C,'Hiker Food'!G:G)*D30)} | F30: {=if(C30="","",_xlfn.xlookup(C30,'Hiker Food'!$C:$C,'Hiker Food'!H:H)*D30)} | G30: {=if($C30="","",_xlfn.xlookup($C30,'Hiker Food'!$C:$C,'Hiker Food'!J:J)*$D30)} | H30: {=if($C30="","",_xlfn.xlookup($C30,'Hiker Food'!$C:$C,'Hiker Food'!K:K)*$D30)} | I30: {=if($C30="","",_xlfn.xlookup($C30,'Hiker Food'!$C:$C,'Hiker Food'!L:L)*$D30)} | J30: {=if($C30="","",_xlfn.xlookup($C30,'Hiker Food'!$C:$C,'Hiker Food'!M:M)*$D30)} | K30: {=if($C30="","",_xlfn.xlookup($C30,'Hiker Food'!$C:$C,'Hiker Food'!N:N)*$D30)} | L30: {=if($C30="","",_xlfn.xlookup($C30,'Hiker Food'!$C:$C,'Hiker Food'!O:O)*$D30)} | M30: {=if($C30="","",_xlfn.xlookup($C30,'Hiker Food'!$C:$C,'Hiker Food'!P:P)*$D30)} | N30: {=if($C30="","",_xlfn.xlookup($C30,'Hiker Food'!$C:$C,'Hiker Food'!Q:Q)*$D30)} | O30: {=if($C30="","",_xlfn.xlookup($C30,'Hiker Food'!$C:$C,'Hiker Food'!I:I)*$D30)} | P30: {=if($C30="","",_xlfn.xlookup($C30,'Hiker Food'!$C:$C,'Hiker Food'!T:T))} | Q30: {=if($C30="","",_xlfn.xlookup($C30,'Hiker Food'!$C:$C,'Hiker Food'!U:U))} | R30: {=if($C30="","",_xlfn.xlookup($C30,'Hiker Food'!$C:$C,'Hiker Food'!V:V))} | S30: {=if($C30="","",_xlfn.xlookup($C30,'Hiker Food'!$C:$C,'Hiker Food'!W:W))} | T30: Lunch | U30: =if(C30="","",Y30/V30) | V30: =if($C30="","",sum(E30:E32)) | W30: =if($C30="","",$Y30/X30) | X30: =if($C30="","",sum(F30:F32)) | Y30: =if($C30="","",sum(O30:O32)) | Z30: =if($C30="","",(sum(J30:J32)/sum(N30:N32))) | AA30: =if($C30="","",sum(G30:G32)*9/sum(sum(G30:G32)*9+sum(J30:J32)*4+sum(N30:N32)*4)) | AB30: =if($C30="","",sum(L30:L32)*4/sum(sum(G30:G32)*9+sum(J30:J32)*4+sum(N30:N32)*4)) | AC30: =if($C30="","",(sum(H30:H32)/sum(O30:O32)))
D31: 3 | E31: {=if(C31="","",_xlfn.xlookup(C31,'Hiker Food'!$C:$C,'Hiker Food'!G:G)*D31)} | F31: {=if(C31="","",_xlfn.xlookup(C31,'Hiker Food'!$C:$C,'Hiker Food'!H:H)*D31)} | G31: {=if($C31="","",_xlfn.xlookup($C31,'Hiker Food'!$C:$C,'Hiker Food'!J:J)*$D31)} | H31: {=if($C31="","",_xlfn.xlookup($C31,'Hiker Food'!$C:$C,'Hiker Food'!K:K)*$D31)} | I31: {=if($C31="","",_xlfn.xlookup($C31,'Hiker Food'!$C:$C,'Hiker Food'!L:L)*$D31)} | J31: {=if($C31="","",_xlfn.xlookup($C31,'Hiker Food'!$C:$C,'Hiker Food'!M:M)*$D31)} | K31: {=if($C31="","",_xlfn.xlookup($C31,'Hiker Food'!$C:$C,'Hiker Food'!N:N)*$D31)} | L31: {=if($C31="","",_xlfn.xlookup($C31,'Hiker Food'!$C:$C,'Hiker Food'!O:O)*$D31)} | M31: {=if($C31="","",_xlfn.xlookup($C31,'Hiker Food'!$C:$C,'Hiker Food'!P:P)*$D31)} | N31: {=if($C31="","",_xlfn.xlookup($C31,'Hiker Food'!$C:$C,'Hiker Food'!Q:Q)*$D31)} | O31: {=if($C31="","",_xlfn.xlookup($C31,'Hiker Food'!$C:$C,'Hiker Food'!I:I)*$D31)} | P31: {=if($C31="","",_xlfn.xlookup($C31,'Hiker Food'!$C:$C,'Hiker Food'!T:T))} | Q31: {=if($C31="","",_xlfn.xlookup($C31,'Hiker Food'!$C:$C,'Hiker Food'!U:U))} | R31: {=if($C31="","",_xlfn.xlookup($C31,'Hiker Food'!$C:$C,'Hiker Food'!V:V))} | S31: {=if($C31="","",_xlfn.xlookup($C31,'Hiker Food'!$C:$C,'Hiker Food'!W:W))}
D32: 1 | E32: {=if(C32="","",_xlfn.xlookup(C32,'Hiker Food'!$C:$C,'Hiker Food'!G:G)*D32)} | F32: {=if(C32="","",_xlfn.xlookup(C32,'Hiker Food'!$C:$C,'Hiker Food'!H:H)*D32)} | G32: {=if($C32="","",_xlfn.xlookup($C32,'Hiker Food'!$C:$C,'Hiker Food'!J:J)*$D32)} | H32: {=if($C32="","",_xlfn.xlookup($C32,'Hiker Food'!$C:$C,'Hiker Food'!K:K)*$D32)} | I32: {=if($C32="","",_xlfn.xlookup($C32,'Hiker Food'!$C:$C,'Hiker Food'!L:L)*$D32)} | J32: {=if($C32="","",_xlfn.xlookup($C32,'Hiker Food'!$C:$C,'Hiker Food'!M:M)*$D32)} | K32: {=if($C32="","",_xlfn.xlookup($C32,'Hiker Food'!$C:$C,'Hiker Food'!N:N)*$D32)} | L32: {=if($C32="","",_xlfn.xlookup($C32,'Hiker Food'!$C:$C,'Hiker Food'!O:O)*$D32)} | M32: {=if($C32="","",_xlfn.xlookup($C32,'Hiker Food'!$C:$C,'Hiker Food'!P:P)*$D32)} | N32: {=if($C32="","",_xlfn.xlookup($C32,'Hiker Food'!$C:$C,'Hiker Food'!Q:Q)*$D32)} | O32: {=if($C32="","",_xlfn.xlookup($C32,'Hiker Food'!$C:$C,'Hiker Food'!I:I)*$D32)} | P32: {=if($C32="","",_xlfn.xlookup($C32,'Hiker Food'!$C:$C,'Hiker Food'!T:T))} | Q32: {=if($C32="","",_xlfn.xlookup($C32,'Hiker Food'!$C:$C,'Hiker Food'!U:U))} | R32: {=if($C32="","",_xlfn.xlookup($C32,'Hiker Food'!$C:$C,'Hiker Food'!V:V))} | S32: {=if($C32="","",_xlfn.xlookup($C32,'Hiker Food'!$C:$C,'Hiker Food'!W:W))}
B33: Afternoon Snacks | D33: 1 | E33: {=if(C33="","",_xlfn.xlookup(C33,'Hiker Food'!$C:$C,'Hiker Food'!G:G)*D33)} | F33: {=if(C33="","",_xlfn.xlookup(C33,'Hiker Food'!$C:$C,'Hiker Food'!H:H)*D33)} | G33: {=if($C33="","",_xlfn.xlookup($C33,'Hiker Food'!$C:$C,'Hiker Food'!J:J)*$D33)} | H33: {=if($C33="","",_xlfn.xlookup($C33,'Hiker Food'!$C:$C,'Hiker Food'!K:K)*$D33)} | I33: {=if($C33="","",_xlfn.xlookup($C33,'Hiker Food'!$C:$C,'Hiker Food'!L:L)*$D33)} | J33: {=if($C33="","",_xlfn.xlookup($C33,'Hiker Food'!$C:$C,'Hiker Food'!M:M)*$D33)} | K33: {=if($C33="","",_xlfn.xlookup($C33,'Hiker Food'!$C:$C,'Hiker Food'!N:N)*$D33)} | L33: {=if($C33="","",_xlfn.xlookup($C33,'Hiker Food'!$C:$C,'Hiker Food'!O:O)*$D33)} | M33: {=if($C33="","",_xlfn.xlookup($C33,'Hiker Food'!$C:$C,'Hiker Food'!P:P)*$D33)} | N33: {=if($C33="","",_xlfn.xlookup($C33,'Hiker Food'!$C:$C,'Hiker Food'!Q:Q)*$D33)} | O33: {=if($C33="","",_xlfn.xlookup($C33,'Hiker Food'!$C:$C,'Hiker Food'!I:I)*$D33)} | P33: {=if($C33="","",_xlfn.xlookup($C33,'Hiker Food'!$C:$C,'Hiker Food'!T:T))} | Q33: {=if($C33="","",_xlfn.xlookup($C33,'Hiker Food'!$C:$C,'Hiker Food'!U:U))} | R33: {=if($C33="","",_xlfn.xlookup($C33,'Hiker Food'!$C:$C,'Hiker Food'!V:V))} | S33: {=if($C33="","",_xlfn.xlookup($C33,'Hiker Food'!$C:$C,'Hiker Food'!W:W))} | T33: Afternoon Snacks | U33: =if(C33="","",Y33/V33) | V33: =if($C33="","",sum(E33:E35)) | W33: =if($C33="","",$Y33/X33) | X33: =if($C33="","",sum(F33:F35)) | Y33: =if($C33="","",sum(O33:O35)) | Z33: =if($C33="","",(sum(J33:J35)/sum(N33:N35))) | AA33: =if($C33="","",sum(G33:G35)*9/sum(sum(G33:G35)*9+sum(J33:J35)*4+sum(N33:N35)*4)) | AB33: =if($C33="","",sum(L33:L35)*4/sum(sum(G33:G35)*9+sum(J33:J35)*4+sum(N33:N35)*4)) | AC33: =if($C33="","",(sum(H33:H35)/sum(O33:O35)))
D34: 1 | E34: {=if(C34="","",_xlfn.xlookup(C34,'Hiker Food'!$C:$C,'Hiker Food'!G:G)*D34)} | F34: {=if(C34="","",_xlfn.xlookup(C34,'Hiker Food'!$C:$C,'Hiker Food'!H:H)*D34)} | G34: {=if($C34="","",_xlfn.xlookup($C34,'Hiker Food'!$C:$C,'Hiker Food'!J:J)*$D34)} | H34: {=if($C34="","",_xlfn.xlookup($C34,'Hiker Food'!$C:$C,'Hiker Food'!K:K)*$D34)} | I34: {=if($C34="","",_xlfn.xlookup($C34,'Hiker Food'!$C:$C,'Hiker Food'!L:L)*$D34)} | J34: {=if($C34="","",_xlfn.xlookup($C34,'Hiker Food'!$C:$C,'Hiker Food'!M:M)*$D34)} | K34: {=if($C34="","",_xlfn.xlookup($C34,'Hiker Food'!$C:$C,'Hiker Food'!N:N)*$D34)} | L34: {=if($C34="","",_xlfn.xlookup($C34,'Hiker Food'!$C:$C,'Hiker Food'!O:O)*$D34)} | M34: {=if($C34="","",_xlfn.xlookup($C34,'Hiker Food'!$C:$C,'Hiker Food'!P:P)*$D34)} | N34: {=if($C34="","",_xlfn.xlookup($C34,'Hiker Food'!$C:$C,'Hiker Food'!Q:Q)*$D34)} | O34: {=if($C34="","",_xlfn.xlookup($C34,'Hiker Food'!$C:$C,'Hiker Food'!I:I)*$D34)} | P34: {=if($C34="","",_xlfn.xlookup($C34,'Hiker Food'!$C:$C,'Hiker Food'!T:T))} | Q34: {=if($C34="","",_xlfn.xlookup($C34,'Hiker Food'!$C:$C,'Hiker Food'!U:U))} | R34: {=if($C34="","",_xlfn.xlookup($C34,'Hiker Food'!$C:$C,'Hiker Food'!V:V))} | S34: {=if($C34="","",_xlfn.xlookup($C34,'Hiker Food'!$C:$C,'Hiker Food'!W:W))}
D35: 1 | E35: {=if(C35="","",_xlfn.xlookup(C35,'Hiker Food'!$C:$C,'Hiker Food'!G:G)*D35)} | F35: {=if(C35="","",_xlfn.xlookup(C35,'Hiker Food'!$C:$C,'Hiker Food'!H:H)*D35)} | G35: {=if($C35="","",_xlfn.xlookup($C35,'Hiker Food'!$C:$C,'Hiker Food'!J:J)*$D35)} | H35: {=if($C35="","",_xlfn.xlookup($C35,'Hiker Food'!$C:$C,'Hiker Food'!K:K)*$D35)} | I35: {=if($C35="","",_xlfn.xlookup($C35,'Hiker Food'!$C:$C,'Hiker Food'!L:L)*$D35)} | J35: {=if($C35="","",_xlfn.xlookup($C35,'Hiker Food'!$C:$C,'Hiker Food'!M:M)*$D35)} | K35: {=if($C35="","",_xlfn.xlookup($C35,'Hiker Food'!$C:$C,'Hiker Food'!N:N)*$D35)} | L35: {=if($C35="","",_xlfn.xlookup($C35,'Hiker Food'!$C:$C,'Hiker Food'!O:O)*$D35)} | M35: {=if($C35="","",_xlfn.xlookup($C35,'Hiker Food'!$C:$C,'Hiker Food'!P:P)*$D35)} | N35: {=if($C35="","",_xlfn.xlookup($C35,'Hiker Food'!$C:$C,'Hiker Food'!Q:Q)*$D35)} | O35: {=if($C35="","",_xlfn.xlookup($C35,'Hiker Food'!$C:$C,'Hiker Food'!I:I)*$D35)} | P35: {=if($C35="","",_xlfn.xlookup($C35,'Hiker Food'!$C:$C,'Hiker Food'!T:T))} | Q35: {=if($C35="","",_xlfn.xlookup($C35,'Hiker Food'!$C:$C,'Hiker Food'!U:U))} | R35: {=if($C35="","",_xlfn.xlookup($C35,'Hiker Food'!$C:$C,'Hiker Food'!V:V))} | S35: {=if($C35="","",_xlfn.xlookup($C35,'Hiker Food'!$C:$C,'Hiker Food'!W:W))}
B36: Recovery | D36: 1 | E36: {=if(C36="","",_xlfn.xlookup(C36,'Hiker Food'!$C:$C,'Hiker Food'!G:G)*D36)} | F36: {=if(C36="","",_xlfn.xlookup(C36,'Hiker Food'!$C:$C,'Hiker Food'!H:H)*D36)} | G36: {=if($C36="","",_xlfn.xlookup($C36,'Hiker Food'!$C:$C,'Hiker Food'!J:J)*$D36)} | H36: {=if($C36="","",_xlfn.xlookup($C36,'Hiker Food'!$C:$C,'Hiker Food'!K:K)*$D36)} | I36: {=if($C36="","",_xlfn.xlookup($C36,'Hiker Food'!$C:$C,'Hiker Food'!L:L)*$D36)} | J36: {=if($C36="","",_xlfn.xlookup($C36,'Hiker Food'!$C:$C,'Hiker Food'!M:M)*$D36)} | K36: {=if($C36="","",_xlfn.xlookup($C36,'Hiker Food'!$C:$C,'Hiker Food'!N:N)*$D36)} | L36: {=if($C36="","",_xlfn.xlookup($C36,'Hiker Food'!$C:$C,'Hiker Food'!O:O)*$D36)} | M36: {=if($C36="","",_xlfn.xlookup($C36,'Hiker Food'!$C:$C,'Hiker Food'!P:P)*$D36)} | N36: {=if($C36="","",_xlfn.xlookup($C36,'Hiker Food'!$C:$C,'Hiker Food'!Q:Q)*$D36)} | O36: {=if($C36="","",_xlfn.xlookup($C36,'Hiker Food'!$C:$C,'Hiker Food'!I:I)*$D36)} | P36: {=if($C36="","",_xlfn.xlookup($C36,'Hiker Food'!$C:$C,'Hiker Food'!T:T))} | Q36: {=if($C36="","",_xlfn.xlookup($C36,'Hiker Food'!$C:$C,'Hiker Food'!U:U))} | R36: {=if($C36="","",_xlfn.xlookup($C36,'Hiker Food'!$C:$C,'Hiker Food'!V:V))} | S36: {=if($C36="","",_xlfn.xlookup($C36,'Hiker Food'!$C:$C,'Hiker Food'!W:W))} | T36: Recovery | U36: =if(C36="","",Y36/V36) | V36: =if($C36="","",sum(E36:E38)) | W36: =if($C36="","",$Y36/X36) | X36: =if($C36="","",sum(F36:F38)) | Y36: =if($C36="","",sum(O36:O38)) | Z36: =if($C36="","",(sum(J36:J38)/sum(N36:N38))) | AA36: =if($C36="","",sum(G36:G38)*9/sum(sum(G36:G38)*9+sum(J36:J38)*4+sum(N36:N38)*4)) | AB36: =if($C36="","",sum(L36:L38)*4/sum(sum(G36:G38)*9+sum(J36:J38)*4+sum(N36:N38)*4)) | AC36: =if($C36="","",(sum(H36:H38)/sum(O36:O38)))
D37: 1 | E37: {=if(C37="","",_xlfn.xlookup(C37,'Hiker Food'!$C:$C,'Hiker Food'!G:G)*D37)} | F37: {=if(C37="","",_xlfn.xlookup(C37,'Hiker Food'!$C:$C,'Hiker Food'!H:H)*D37)} | G37: {=if($C37="","",_xlfn.xlookup($C37,'Hiker Food'!$C:$C,'Hiker Food'!J:J)*$D37)} | H37: {=if($C37="","",_xlfn.xlookup($C37,'Hiker Food'!$C:$C,'Hiker Food'!K:K)*$D37)} | I37: {=if($C37="","",_xlfn.xlookup($C37,'Hiker Food'!$C:$C,'Hiker Food'!L:L)*$D37)} | J37: {=if($C37="","",_xlfn.xlookup($C37,'Hiker Food'!$C:$C,'Hiker Food'!M:M)*$D37)} | K37: {=if($C37="","",_xlfn.xlookup($C37,'Hiker Food'!$C:$C,'Hiker Food'!N:N)*$D37)} | L37: {=if($C37="","",_xlfn.xlookup($C37,'Hiker Food'!$C:$C,'Hiker Food'!O:O)*$D37)} | M37: {=if($C37="","",_xlfn.xlookup($C37,'Hiker Food'!$C:$C,'Hiker Food'!P:P)*$D37)} | N37: {=if($C37="","",_xlfn.xlookup($C37,'Hiker Food'!$C:$C,'Hiker Food'!Q:Q)*$D37)} | O37: {=if($C37="","",_xlfn.xlookup($C37,'Hiker Food'!$C:$C,'Hiker Food'!I:I)*$D37)} | P37: {=if($C37="","",_xlfn.xlookup($C37,'Hiker Food'!$C:$C,'Hiker Food'!T:T))} | Q37: {=if($C37="","",_xlfn.xlookup($C37,'Hiker Food'!$C:$C,'Hiker Food'!U:U))} | R37: {=if($C37="","",_xlfn.xlookup($C37,'Hiker Food'!$C:$C,'Hiker Food'!V:V))} | S37: {=if($C37="","",_xlfn.xlookup($C37,'Hiker Food'!$C:$C,'Hiker Food'!W:W))}
D38: 1 | E38: {=if(C38="","",_xlfn.xlookup(C38,'Hiker Food'!$C:$C,'Hiker Food'!G:G)*D38)} | F38: {=if(C38="","",_xlfn.xlookup(C38,'Hiker Food'!$C:$C,'Hiker Food'!H:H)*D38)} | G38: {=if($C38="","",_xlfn.xlookup($C38,'Hiker Food'!$C:$C,'Hiker Food'!J:J)*$D38)} | H38: {=if($C38="","",_xlfn.xlookup($C38,'Hiker Food'!$C:$C,'Hiker Food'!K:K)*$D38)} | I38: {=if($C38="","",_xlfn.xlookup($C38,'Hiker Food'!$C:$C,'Hiker Food'!L:L)*$D38)} | J38: {=if($C38="","",_xlfn.xlookup($C38,'Hiker Food'!$C:$C,'Hiker Food'!M:M)*$D38)} | K38: {=if($C38="","",_xlfn.xlookup($C38,'Hiker Food'!$C:$C,'Hiker Food'!N:N)*$D38)} | L38: {=if($C38="","",_xlfn.xlookup($C38,'Hiker Food'!$C:$C,'Hiker Food'!O:O)*$D38)} | M38: {=if($C38="","",_xlfn.xlookup($C38,'Hiker Food'!$C:$C,'Hiker Food'!P:P)*$D38)} | N38: {=if($C38="","",_xlfn.xlookup($C38,'Hiker Food'!$C:$C,'Hiker Food'!Q:Q)*$D38)} | O38: {=if($C38="","",_xlfn.xlookup($C38,'Hiker Food'!$C:$C,'Hiker Food'!I:I)*$D38)} | P38: {=if($C38="","",_xlfn.xlookup($C38,'Hiker Food'!$C:$C,'Hiker Food'!T:T))} | Q38: {=if($C38="","",_xlfn.xlookup($C38,'Hiker Food'!$C:$C,'Hiker Food'!U:U))} | R38: {=if($C38="","",_xlfn.xlookup($C38,'Hiker Food'!$C:$C,'Hiker Food'!V:V))} | S38: {=if($C38="","",_xlfn.xlookup($C38,'Hiker Food'!$C:$C,'Hiker Food'!W:W))}
B39: Dinner | D39: 1 | E39: {=if(C39="","",_xlfn.xlookup(C39,'Hiker Food'!$C:$C,'Hiker Food'!G:G)*D39)} | F39: {=if(C39="","",_xlfn.xlookup(C39,'Hiker Food'!$C:$C,'Hiker Food'!H:H)*D39)} | G39: {=if($C39="","",_xlfn.xlookup($C39,'Hiker Food'!$C:$C,'Hiker Food'!J:J)*$D39)} | H39: {=if($C39="","",_xlfn.xlookup($C39,'Hiker Food'!$C:$C,'Hiker Food'!K:K)*$D39)} | I39: {=if($C39="","",_xlfn.xlookup($C39,'Hiker Food'!$C:$C,'Hiker Food'!L:L)*$D39)} | J39: {=if($C39="","",_xlfn.xlookup($C39,'Hiker Food'!$C:$C,'Hiker Food'!M:M)*$D39)} | K39: {=if($C39="","",_xlfn.xlookup($C39,'Hiker Food'!$C:$C,'Hiker Food'!N:N)*$D39)} | L39: {=if($C39="","",_xlfn.xlookup($C39,'Hiker Food'!$C:$C,'Hiker Food'!O:O)*$D39)} | M39: {=if($C39="","",_xlfn.xlookup($C39,'Hiker Food'!$C:$C,'Hiker Food'!P:P)*$D39)} | N39: {=if($C39="","",_xlfn.xlookup($C39,'Hiker Food'!$C:$C,'Hiker Food'!Q:Q)*$D39)} | O39: {=if($C39="","",_xlfn.xlookup($C39,'Hiker Food'!$C:$C,'Hiker Food'!I:I)*$D39)} | P39: {=if($C39="","",_xlfn.xlookup($C39,'Hiker Food'!$C:$C,'Hiker Food'!T:T))} | Q39: {=if($C39="","",_xlfn.xlookup($C39,'Hiker Food'!$C:$C,'Hiker Food'!U:U))} | R39: {=if($C39="","",_xlfn.xlookup($C39,'Hiker Food'!$C:$C,'Hiker Food'!V:V))} | S39: {=if($C39="","",_xlfn.xlookup($C39,'Hiker Food'!$C:$C,'Hiker Food'!W:W))} | T39: Dinner | U39: =if(C39="","",Y39/V39) | V39: =if($C39="","",sum(E39:E41)) | W39: =if($C39="","",$Y39/X39) | X39: =if($C39="","",sum(F39:F41)) | Y39: =if($C39="","",sum(O39:O41)) | Z39: =if($C39="","",(sum(J39:J41)/sum(N39:N41))) | AA39: =if($C39="","",sum(G39:G41)*9/sum(sum(G39:G41)*9+sum(J39:J41)*4+sum(N39:N41)*4)) | AB39: =if($C39="","",sum(L39:L41)*4/sum(sum(G39:G41)*9+sum(J39:J41)*4+sum(N39:N41)*4)) | AC39: =if($C39="","",(sum(H39:H41)/sum(O39:O41)))
D40: 1 | E40: {=if(C40="","",_xlfn.xlookup(C40,'Hiker Food'!$C:$C,'Hiker Food'!G:G)*D40)} | F40: {=if(C40="","",_xlfn.xlookup(C40,'Hiker Food'!$C:$C,'Hiker Food'!H:H)*D40)} | G40: {=if($C40="","",_xlfn.xlookup($C40,'Hiker Food'!$C:$C,'Hiker Food'!J:J)*$D40)} | H40: {=if($C40="","",_xlfn.xlookup($C40,'Hiker Food'!$C:$C,'Hiker Food'!K:K)*$D40)} | I40: {=if($C40="","",_xlfn.xlookup($C40,'Hiker Food'!$C:$C,'Hiker Food'!L:L)*$D40)} | J40: {=if($C40="","",_xlfn.xlookup($C40,'Hiker Food'!$C:$C,'Hiker Food'!M:M)*$D40)} | K40: {=if($C40="","",_xlfn.xlookup($C40,'Hiker Food'!$C:$C,'Hiker Food'!N:N)*$D40)} | L40: {=if($C40="","",_xlfn.xlookup($C40,'Hiker Food'!$C:$C,'Hiker Food'!O:O)*$D40)} | M40: {=if($C40="","",_xlfn.xlookup($C40,'Hiker Food'!$C:$C,'Hiker Food'!P:P)*$D40)} | N40: {=if($C40="","",_xlfn.xlookup($C40,'Hiker Food'!$C:$C,'Hiker Food'!Q:Q)*$D40)} | O40: {=if($C40="","",_xlfn.xlookup($C40,'Hiker Food'!$C:$C,'Hiker Food'!I:I)*$D40)} | P40: {=if($C40="","",_xlfn.xlookup($C40,'Hiker Food'!$C:$C,'Hiker Food'!T:T))} | Q40: {=if($C40="","",_xlfn.xlookup($C40,'Hiker Food'!$C:$C,'Hiker Food'!U:U))} | R40: {=if($C40="","",_xlfn.xlookup($C40,'Hiker Food'!$C:$C,'Hiker Food'!V:V))} | S40: {=if($C40="","",_xlfn.xlookup($C40,'Hiker Food'!$C:$C,'Hiker Food'!W:W))}
...

Sheet Shopping List
A1: Shopping list

Sheet Hiker Food
A1: Brand | B1: Flavor | C1: Full name | D1: Class | E1: Prep | F1: Servings | G1: Serv(oz) | H1: Serv(g) | I1: Cal/Serv | J1: Fat | K1: Na | L1: K | M1: Carbs | N1: Fiber | O1: Sugar | P1: Other | Q1: Protein | R1: kcal/oz | S1: kcal/g | T1: Carb/Pro | U1: Fat % | V1: Sugar % | W1: Na/kcal | X1: Cal/Cont
